Failure # 1 (occurred at 2022-10-04_15-46-18)
Traceback (most recent call last):
  File "/home/anthony/.pyenv/versions/py39/lib/python3.9/site-packages/ray/tune/execution/ray_trial_executor.py", line 989, in get_next_executor_event
    future_result = ray.get(ready_future)
  File "/home/anthony/.pyenv/versions/py39/lib/python3.9/site-packages/ray/_private/client_mode_hook.py", line 105, in wrapper
    return func(*args, **kwargs)
  File "/home/anthony/.pyenv/versions/py39/lib/python3.9/site-packages/ray/_private/worker.py", line 2277, in get
    raise value
ray.exceptions.RayActorError: The actor died because of an error raised in its creation task, [36mray::ApexDQN.__init__()[39m (pid=96734, ip=143.248.153.115, repr=ApexDQN)
  File "/home/anthony/.pyenv/versions/py39/lib/python3.9/site-packages/ray/rllib/evaluation/worker_set.py", line 125, in __init__
    self.add_workers(
  File "/home/anthony/.pyenv/versions/py39/lib/python3.9/site-packages/ray/rllib/evaluation/worker_set.py", line 269, in add_workers
    self.foreach_worker(lambda w: w.assert_healthy())
  File "/home/anthony/.pyenv/versions/py39/lib/python3.9/site-packages/ray/rllib/evaluation/worker_set.py", line 391, in foreach_worker
    remote_results = ray.get([w.apply.remote(func) for w in self.remote_workers()])
ray.exceptions.RayActorError: The actor died because of an error raised in its creation task, [36mray::RolloutWorker.__init__()[39m (pid=96780, ip=143.248.153.115, repr=<ray.rllib.evaluation.rollout_worker.RolloutWorker object at 0x7f15f7e3a0d0>)
  File "/home/anthony/.pyenv/versions/py39/lib/python3.9/site-packages/ray/rllib/utils/pre_checks/env.py", line 193, in check_gym_environments
    next_obs, reward, done, info = env.step(sampled_action)
  File "/home/anthony/physics-informed-metasurface/pirl/env.py", line 76, in step
    self.eff = self.eval_eff_1d(
  File "/home/anthony/physics-informed-metasurface/pirl/env.py", line 57, in eval_eff_1d
    effs = self.eng.Eval_Eff_1D(struct, wavelength, desired_angle)
  File "/home/anthony/.pyenv/versions/py39/lib/python3.9/site-packages/matlab/engine/matlabengine.py", line 70, in __call__
    return FutureResult(self._engine(), future, nargs, _stdout,
  File "/home/anthony/.pyenv/versions/py39/lib/python3.9/site-packages/matlab/engine/futureresult.py", line 67, in result
    return self.__future.result(timeout)
  File "/home/anthony/.pyenv/versions/py39/lib/python3.9/site-packages/matlab/engine/fevalfuture.py", line 82, in result
    self._result = pythonengine.getFEvalResult(self._future,self._nargout, None, out=self._out, err=self._err)
matlab.engine.MatlabExecutionError: Undefined function 'Eval_Eff_1D' for input arguments of type 'double'.


During handling of the above exception, another exception occurred:

[36mray::RolloutWorker.__init__()[39m (pid=96780, ip=143.248.153.115, repr=<ray.rllib.evaluation.rollout_worker.RolloutWorker object at 0x7f15f7e3a0d0>)
  File "/home/anthony/.pyenv/versions/py39/lib/python3.9/site-packages/ray/rllib/evaluation/rollout_worker.py", line 495, in __init__
    check_env(self.env)
  File "/home/anthony/.pyenv/versions/py39/lib/python3.9/site-packages/ray/rllib/utils/pre_checks/env.py", line 83, in check_env
    raise ValueError(
ValueError: Traceback (most recent call last):
  File "/home/anthony/.pyenv/versions/py39/lib/python3.9/site-packages/ray/rllib/utils/pre_checks/env.py", line 72, in check_env
    check_gym_environments(env)
  File "/home/anthony/.pyenv/versions/py39/lib/python3.9/site-packages/ray/rllib/utils/pre_checks/env.py", line 193, in check_gym_environments
    next_obs, reward, done, info = env.step(sampled_action)
  File "/home/anthony/physics-informed-metasurface/pirl/env.py", line 76, in step
    self.eff = self.eval_eff_1d(
  File "/home/anthony/physics-informed-metasurface/pirl/env.py", line 57, in eval_eff_1d
    effs = self.eng.Eval_Eff_1D(struct, wavelength, desired_angle)
  File "/home/anthony/.pyenv/versions/py39/lib/python3.9/site-packages/matlab/engine/matlabengine.py", line 70, in __call__
    return FutureResult(self._engine(), future, nargs, _stdout,
  File "/home/anthony/.pyenv/versions/py39/lib/python3.9/site-packages/matlab/engine/futureresult.py", line 67, in result
    return self.__future.result(timeout)
  File "/home/anthony/.pyenv/versions/py39/lib/python3.9/site-packages/matlab/engine/fevalfuture.py", line 82, in result
    self._result = pythonengine.getFEvalResult(self._future,self._nargout, None, out=self._out, err=self._err)
matlab.engine.MatlabExecutionError: Undefined function 'Eval_Eff_1D' for input arguments of type 'double'.


The above error has been found in your environment! We've added a module for checking your custom environments. It may cause your experiment to fail if your environment is not set up correctly. You can disable this behavior by setting `disable_env_checking=True` in your environment config dictionary. You can run the environment checking module standalone by calling ray.rllib.utils.check_env([env]).

During handling of the above exception, another exception occurred:

[36mray::ApexDQN.__init__()[39m (pid=96734, ip=143.248.153.115, repr=ApexDQN)
  File "/home/anthony/.pyenv/versions/py39/lib/python3.9/site-packages/ray/rllib/algorithms/algorithm.py", line 308, in __init__
    super().__init__(config=config, logger_creator=logger_creator, **kwargs)
  File "/home/anthony/.pyenv/versions/py39/lib/python3.9/site-packages/ray/tune/trainable/trainable.py", line 157, in __init__
    self.setup(copy.deepcopy(self.config))
  File "/home/anthony/.pyenv/versions/py39/lib/python3.9/site-packages/ray/rllib/algorithms/apex_dqn/apex_dqn.py", line 349, in setup
    super().setup(config)
  File "/home/anthony/.pyenv/versions/py39/lib/python3.9/site-packages/ray/rllib/algorithms/algorithm.py", line 443, in setup
    raise e.args[0].args[2]
ValueError: Traceback (most recent call last):
  File "/home/anthony/.pyenv/versions/py39/lib/python3.9/site-packages/ray/rllib/utils/pre_checks/env.py", line 72, in check_env
    check_gym_environments(env)
  File "/home/anthony/.pyenv/versions/py39/lib/python3.9/site-packages/ray/rllib/utils/pre_checks/env.py", line 193, in check_gym_environments
    next_obs, reward, done, info = env.step(sampled_action)
  File "/home/anthony/physics-informed-metasurface/pirl/env.py", line 76, in step
    self.eff = self.eval_eff_1d(
  File "/home/anthony/physics-informed-metasurface/pirl/env.py", line 57, in eval_eff_1d
    effs = self.eng.Eval_Eff_1D(struct, wavelength, desired_angle)
  File "/home/anthony/.pyenv/versions/py39/lib/python3.9/site-packages/matlab/engine/matlabengine.py", line 70, in __call__
    return FutureResult(self._engine(), future, nargs, _stdout,
  File "/home/anthony/.pyenv/versions/py39/lib/python3.9/site-packages/matlab/engine/futureresult.py", line 67, in result
    return self.__future.result(timeout)
  File "/home/anthony/.pyenv/versions/py39/lib/python3.9/site-packages/matlab/engine/fevalfuture.py", line 82, in result
    self._result = pythonengine.getFEvalResult(self._future,self._nargout, None, out=self._out, err=self._err)
matlab.engine.MatlabExecutionError: Undefined function 'Eval_Eff_1D' for input arguments of type 'double'.


The above error has been found in your environment! We've added a module for checking your custom environments. It may cause your experiment to fail if your environment is not set up correctly. You can disable this behavior by setting `disable_env_checking=True` in your environment config dictionary. You can run the environment checking module standalone by calling ray.rllib.utils.check_env([env]).

